return {{["x"] = 0, ["meta"] = {["fields"] = {}, ["inventory"] = {}}, ["param2"] = 0, ["y"] = 0, ["param1"] = 0, ["z"] = 0, ["name"] = "default:dirt_with_grass"}, {["x"] = 0, ["meta"] = {["fields"] = {}, ["inventory"] = {}}, ["param2"] = 0, ["y"] = 0, ["param1"] = 0, ["z"] = 1, ["name"] = "default:dirt_with_grass"}, {["x"] = 0, ["meta"] = {["fields"] = {}, ["inventory"] = {}}, ["param2"] = 0, ["y"] = 0, ["param1"] = 0, ["z"] = 2, ["name"] = "default:dirt_with_grass"}, {["x"] = 0, ["meta"] = {["fields"] = {}, ["inventory"] = {}}, ["param2"] = 0, ["y"] = 0, ["param1"] = 0, ["z"] = 3, ["name"] = "default:dirt_with_grass"}, {["x"] = 0, ["meta"] = {["fields"] = {}, ["inventory"] = {}}, ["param2"] = 0, ["y"] = 0, ["param1"] = 0, ["z"] = 4, ["name"] = "default:dirt_with_grass"}, {["x"] = 0, ["meta"] = {["fields"] = {}, ["inventory"] = {}}, ["param2"] = 0, ["y"] = 0, ["param1"] = 0, ["z"] = 5, ["name"] = "default:dirt_with_grass"}, {["x"] = 0, ["meta"] = {["fields"] = {["infotext"] = "Adjustable Vacuuming Pneumatic Tube Segment (8m)", ["dist"] = "8", ["tubedir"] = "1", ["formspec"] = "size[2.1,0.8]image[0,0;1,1;pipeworks_mese_sand_tube_inv.png]field[1.3,0.4;1,1;dist;radius;${dist}]bgcolor[#080808BB;true]background[5,5;1,1;gui_formbg.png;true]"}, ["inventory"] = {}}, ["param2"] = 10, ["y"] = 1, ["param1"] = 31, ["z"] = 1, ["name"] = "pipeworks:mese_sand_tube_4"}, {["x"] = 0, ["meta"] = {["fields"] = {["infotext"] = "Adjustable Vacuuming Pneumatic Tube Segment (8m)", ["dist"] = "8", ["tubedir"] = "1", ["formspec"] = "size[2.1,0.8]image[0,0;1,1;pipeworks_mese_sand_tube_inv.png]field[1.3,0.4;1,1;dist;radius;${dist}]bgcolor[#080808BB;true]background[5,5;1,1;gui_formbg.png;true]"}, ["inventory"] = {}}, ["param2"] = 1, ["y"] = 1, ["param1"] = 47, ["z"] = 2, ["name"] = "pipeworks:mese_sand_tube_3"}, {["x"] = 0, ["meta"] = {["fields"] = {["infotext"] = "Adjustable Vacuuming Pneumatic Tube Segment (8m)", ["dist"] = "8", ["tubedir"] = "1", ["formspec"] = "size[2.1,0.8]image[0,0;1,1;pipeworks_mese_sand_tube_inv.png]field[1.3,0.4;1,1;dist;radius;${dist}]bgcolor[#080808BB;true]background[5,5;1,1;gui_formbg.png;true]"}, ["inventory"] = {}}, ["param2"] = 1, ["y"] = 1, ["param1"] = 31, ["z"] = 3, ["name"] = "pipeworks:mese_sand_tube_3"}, {["x"] = 0, ["meta"] = {["fields"] = {["infotext"] = "Adjustable Vacuuming Pneumatic Tube Segment (8m)", ["dist"] = "8", ["tubedir"] = "1", ["formspec"] = "size[2.1,0.8]image[0,0;1,1;pipeworks_mese_sand_tube_inv.png]field[1.3,0.4;1,1;dist;radius;${dist}]bgcolor[#080808BB;true]background[5,5;1,1;gui_formbg.png;true]"}, ["inventory"] = {}}, ["param2"] = 1, ["y"] = 1, ["param1"] = 47, ["z"] = 4, ["name"] = "pipeworks:mese_sand_tube_3"}, {["x"] = 0, ["meta"] = {["fields"] = {["infotext"] = "Adjustable Vacuuming Pneumatic Tube Segment (8m)", ["dist"] = "8", ["tubedir"] = "1", ["formspec"] = "size[2.1,0.8]image[0,0;1,1;pipeworks_mese_sand_tube_inv.png]field[1.3,0.4;1,1;dist;radius;${dist}]bgcolor[#080808BB;true]background[5,5;1,1;gui_formbg.png;true]"}, ["inventory"] = {}}, ["param2"] = 6, ["y"] = 1, ["param1"] = 31, ["z"] = 5, ["name"] = "pipeworks:mese_sand_tube_4"}, {["x"] = 1, ["meta"] = {["fields"] = {}, ["inventory"] = {}}, ["param2"] = 0, ["y"] = 0, ["param1"] = 0, ["z"] = 0, ["name"] = "default:dirt"}, {["x"] = 1, ["meta"] = {["fields"] = {}, ["inventory"] = {}}, ["param2"] = 0, ["y"] = 0, ["param1"] = 0, ["z"] = 1, ["name"] = "default:dirt_with_grass"}, {["x"] = 1, ["meta"] = {["fields"] = {}, ["inventory"] = {}}, ["param2"] = 0, ["y"] = 0, ["param1"] = 0, ["z"] = 2, ["name"] = "default:dirt_with_grass"}, {["x"] = 1, ["meta"] = {["fields"] = {}, ["inventory"] = {}}, ["param2"] = 0, ["y"] = 0, ["param1"] = 0, ["z"] = 3, ["name"] = "default:dirt_with_grass"}, {["x"] = 1, ["meta"] = {["fields"] = {}, ["inventory"] = {}}, ["param2"] = 0, ["y"] = 0, ["param1"] = 0, ["z"] = 4, ["name"] = "default:dirt_with_grass"}, {["x"] = 1, ["meta"] = {["fields"] = {}, ["inventory"] = {}}, ["param2"] = 0, ["y"] = 0, ["param1"] = 0, ["z"] = 5, ["name"] = "default:dirt_with_grass"}, {["x"] = 1, ["meta"] = {["fields"] = {["infotext"] = "Adjustable Vacuuming Pneumatic Tube Segment (8m)", ["dist"] = "8", ["tubedir"] = "1", ["formspec"] = "size[2.1,0.8]image[0,0;1,1;pipeworks_mese_sand_tube_inv.png]field[1.3,0.4;1,1;dist;radius;${dist}]bgcolor[#080808BB;true]background[5,5;1,1;gui_formbg.png;true]"}, ["inventory"] = {}}, ["param2"] = 0, ["y"] = 1, ["param1"] = 47, ["z"] = 1, ["name"] = "pipeworks:mese_sand_tube_3"}, {["x"] = 1, ["meta"] = {["fields"] = {}, ["inventory"] = {}}, ["param2"] = 0, ["y"] = 1, ["param1"] = 62, ["z"] = 2, ["name"] = "default:mese"}, {["x"] = 1, ["meta"] = {["fields"] = {}, ["inventory"] = {}}, ["param2"] = 1, ["y"] = 1, ["param1"] = 46, ["z"] = 3, ["name"] = "mesecons_delayer:delayer_off_1"}, {["x"] = 1, ["meta"] = {["fields"] = {}, ["inventory"] = {}}, ["param2"] = 0, ["y"] = 1, ["param1"] = 62, ["z"] = 4, ["name"] = "default:mese"}, {["x"] = 1, ["meta"] = {["fields"] = {["dist"] = "8", ["infotext"] = "Adjustable Vacuuming Pneumatic Tube Segment (8m)", ["tubedir"] = "1", ["formspec"] = "size[2.1,0.8]image[0,0;1,1;pipeworks_mese_sand_tube_inv.png]field[1.3,0.4;1,1;dist;radius;${dist}]bgcolor[#080808BB;true]background[5,5;1,1;gui_formbg.png;true]"}, ["inventory"] = {}}, ["param2"] = 0, ["y"] = 1, ["param1"] = 47, ["z"] = 5, ["name"] = "pipeworks:mese_sand_tube_3"}, {["x"] = 1, ["meta"] = {["fields"] = {}, ["inventory"] = {}}, ["param2"] = 0, ["y"] = 2, ["param1"] = 62, ["z"] = 4, ["name"] = "default:mese"}, {["x"] = 1, ["meta"] = {["fields"] = {}, ["inventory"] = {}}, ["param2"] = 0, ["y"] = 3, ["param1"] = 62, ["z"] = 4, ["name"] = "default:mese"}, {["x"] = 1, ["meta"] = {["fields"] = {}, ["inventory"] = {}}, ["param2"] = 0, ["y"] = 4, ["param1"] = 62, ["z"] = 4, ["name"] = "default:mese"}, {["x"] = 1, ["meta"] = {["fields"] = {}, ["inventory"] = {}}, ["param2"] = 0, ["y"] = 5, ["param1"] = 62, ["z"] = 4, ["name"] = "default:mese"}, {["x"] = 1, ["meta"] = {["fields"] = {}, ["inventory"] = {}}, ["param2"] = 0, ["y"] = 6, ["param1"] = 62, ["z"] = 4, ["name"] = "default:mese"}, {["x"] = 1, ["meta"] = {["fields"] = {}, ["inventory"] = {}}, ["param2"] = 0, ["y"] = 7, ["param1"] = 62, ["z"] = 4, ["name"] = "default:mese"}, {["x"] = 1, ["meta"] = {["fields"] = {}, ["inventory"] = {}}, ["param2"] = 0, ["y"] = 8, ["param1"] = 62, ["z"] = 4, ["name"] = "default:mese"}, {["x"] = 1, ["meta"] = {["fields"] = {}, ["inventory"] = {}}, ["param2"] = 0, ["y"] = 9, ["param1"] = 62, ["z"] = 4, ["name"] = "default:mese"}, {["x"] = 1, ["meta"] = {["fields"] = {}, ["inventory"] = {}}, ["param2"] = 0, ["y"] = 10, ["param1"] = 62, ["z"] = 4, ["name"] = "default:mese"}, {["x"] = 1, ["meta"] = {["fields"] = {["distance"] = "0", ["formspec"] = "size[9,2.5]field[0.3,  0;9,2;scanname;Name of node to scan for (empty for any):;${scanname}]field[0.3,1.5;2.5,2;distance;Distance (0-10):;${distance}]field[3,1.5;4,2;digiline_channel;Digiline Channel (optional):;${digiline_channel}]button_exit[7,0.75;2,3;;Save]"}, ["inventory"] = {}}, ["param2"] = 3, ["y"] = 11, ["param1"] = 46, ["z"] = 3, ["name"] = "mesecons_detector:node_detector_off"}, {["x"] = 1, ["meta"] = {["fields"] = {}, ["inventory"] = {}}, ["param2"] = 0, ["y"] = 11, ["param1"] = 62, ["z"] = 4, ["name"] = "default:mese"}, {["x"] = 2, ["meta"] = {["fields"] = {}, ["inventory"] = {}}, ["param2"] = 0, ["y"] = 0, ["param1"] = 0, ["z"] = 0, ["name"] = "default:dirt"}, {["x"] = 2, ["meta"] = {["fields"] = {}, ["inventory"] = {}}, ["param2"] = 0, ["y"] = 0, ["param1"] = 0, ["z"] = 1, ["name"] = "default:dirt_with_grass"}, {["x"] = 2, ["meta"] = {["fields"] = {}, ["inventory"] = {}}, ["param2"] = 0, ["y"] = 0, ["param1"] = 0, ["z"] = 2, ["name"] = "default:dirt"}, {["x"] = 2, ["meta"] = {["fields"] = {}, ["inventory"] = {}}, ["param2"] = 0, ["y"] = 0, ["param1"] = 0, ["z"] = 3, ["name"] = "default:dirt_with_grass"}, {["x"] = 2, ["meta"] = {["fields"] = {}, ["inventory"] = {}}, ["param2"] = 0, ["y"] = 0, ["param1"] = 0, ["z"] = 4, ["name"] = "default:dirt"}, {["x"] = 2, ["meta"] = {["fields"] = {}, ["inventory"] = {}}, ["param2"] = 0, ["y"] = 0, ["param1"] = 0, ["z"] = 5, ["name"] = "default:dirt_with_grass"}, {["x"] = 2, ["meta"] = {["fields"] = {["infotext"] = "Chest"}, ["inventory"] = {["main"] = {"", "", "", "", "", "", "", "", "", "", "", "", "", "", "", "", "", "", "", "", "", "", "", "", "", "", "", "", "", "", "", ""}}}, ["param2"] = 0, ["y"] = 1, ["param1"] = 14, ["z"] = 0, ["name"] = "default:chest"}, {["x"] = 2, ["meta"] = {["fields"] = {["l1s"] = "1", ["formspec"] = "size[8,11]list[context;line1;1,0;6,1;]list[context;line2;1,1;6,1;]list[context;line3;1,2;6,1;]list[context;line4;1,3;6,1;]list[context;line5;1,4;6,1;]list[context;line6;1,5;6,1;]image[0,0;1,1;pipeworks_white.png]image[0,1;1,1;pipeworks_black.png]image[0,2;1,1;pipeworks_green.png]image[0,3;1,1;pipeworks_yellow.png]image[0,4;1,1;pipeworks_blue.png]image[0,5;1,1;pipeworks_red.png]image_button[7,0.2;1,0.6;pipeworks_button_on.png;fs_helpers_cycling:0:l1s;;false;false;pipeworks_button_interm.png]image_button[7,1.2;1,0.6;pipeworks_button_on.png;fs_helpers_cycling:0:l2s;;false;false;pipeworks_button_interm.png]image_button[7,2.2;1,0.6;pipeworks_button_on.png;fs_helpers_cycling:0:l3s;;false;false;pipeworks_button_interm.png]image_button[7,3.2;1,0.6;pipeworks_button_on.png;fs_helpers_cycling:0:l4s;;false;false;pipeworks_button_interm.png]image_button[7,4.2;1,0.6;pipeworks_button_on.png;fs_helpers_cycling:0:l5s;;false;false;pipeworks_button_interm.png]image_button[7,5.2;1,0.6;pipeworks_button_on.png;fs_helpers_cycling:0:l6s;;false;false;pipeworks_button_interm.png]list[current_player;main;0,7;8,4;]listring[current_player;main]listring[current_player;main]listring[context;line1]listring[current_player;main]listring[context;line2]listring[current_player;main]listring[context;line3]listring[current_player;main]listring[context;line4]listring[current_player;main]listring[context;line5]listring[current_player;main]listring[context;line6]", ["tubedir"] = "1", ["l2s"] = "1", ["l4s"] = "1", ["l3s"] = "1", ["infotext"] = "Sorting pneumatic tube", ["l5s"] = "1", ["l6s"] = "1"}, ["inventory"] = {["line6"] = {"", "", "", "", "", ""}, ["line3"] = {"", "", "", "", "", ""}, ["line4"] = {"", "", "", "", "", ""}, ["line1"] = {"default:pine_sapling", "", "", "", "", ""}, ["line5"] = {"", "", "", "", "", ""}, ["line2"] = {"default:pine_tree", "default:pine_needles", "pipeworks:mese_sand_tube_1", "", "", ""}}}, ["param2"] = 0, ["y"] = 1, ["param1"] = 31, ["z"] = 1, ["name"] = "pipeworks:mese_tube_110011"}, {["x"] = 2, ["meta"] = {["fields"] = {["infotext"] = "Deployer", ["owner"] = "singleplayer", ["formspec"] = "invsize[8,9;]item_image[0,0;1,1;pipeworks:deployer_off]label[1,0;Deployer]list[current_name;main;2.5,1;3,3;]list[current_player;main;0,5;8,4;]listring[]"}, ["inventory"] = {["main"] = {"", "", "", "", "", "", "", "", ""}}}, ["param2"] = 2, ["y"] = 1, ["param1"] = 0, ["z"] = 2, ["name"] = "pipeworks:deployer_off"}, {["x"] = 2, ["meta"] = {["fields"] = {["infotext"] = "Node Breaker", ["owner"] = "singleplayer", ["formspec"] = "invsize[8,7;]item_image[0,0;1,1;pipeworks:nodebreaker_off]label[1,0;Node Breaker]list[current_name;pick;3.5,1;1,1;]list[current_player;main;0,3;8,4;]listring[]"}, ["inventory"] = {["ghost_pick"] = {":"}, ["main"] = {"", "", "", "", "", "", "", "", "", "", "", "", "", "", "", "", "", "", "", "", "", "", "", "", "", "", "", "", "", "", "", "", "", "", "", "", "", "", "", "", "", "", "", "", "", "", "", "", "", "", "", "", "", "", "", "", "", "", "", "", "", "", "", "", "", "", "", "", "", "", "", "", "", "", "", "", "", "", "", "", "", "", "", "", "", "", "", "", "", "", "", "", "", "", "", "", "", "", "", ""}, ["pick"] = {""}}}, ["param2"] = 0, ["y"] = 1, ["param1"] = 0, ["z"] = 4, ["name"] = "pipeworks:nodebreaker_off"}, {["x"] = 2, ["meta"] = {["fields"] = {["infotext"] = "Adjustable Vacuuming Pneumatic Tube Segment (8m)", ["dist"] = "8", ["tubedir"] = "1", ["formspec"] = "size[2.1,0.8]image[0,0;1,1;pipeworks_mese_sand_tube_inv.png]field[1.3,0.4;1,1;dist;radius;${dist}]bgcolor[#080808BB;true]background[5,5;1,1;gui_formbg.png;true]"}, ["inventory"] = {}}, ["param2"] = 4, ["y"] = 1, ["param1"] = 31, ["z"] = 5, ["name"] = "pipeworks:mese_sand_tube_7"}, {["x"] = 2, ["meta"] = {["fields"] = {["infotext"] = "Node Breaker", ["owner"] = "singleplayer", ["formspec"] = "invsize[8,7;]item_image[0,0;1,1;pipeworks:nodebreaker_off]label[1,0;Node Breaker]list[current_name;pick;3.5,1;1,1;]list[current_player;main;0,3;8,4;]listring[]"}, ["inventory"] = {["ghost_pick"] = {":"}, ["main"] = {"", "", "", "", "", "", "", "", "", "", "", "", "", "", "", "", "", "", "", "", "", "", "", "", "", "", "", "", "", "", "", "", "", "", "", "", "", "", "", "", "", "", "", "", "", "", "", "", "", "", "", "", "", "", "", "", "", "", "", "", "", "", "", "", "", "", "", "", "", "", "", "", "", "", "", "", "", "", "", "", "", "", "", "", "", "", "", "", "", "", "", "", "", "", "", "", "", "", "", ""}, ["pick"] = {""}}}, ["param2"] = 0, ["y"] = 2, ["param1"] = 0, ["z"] = 4, ["name"] = "pipeworks:nodebreaker_off"}, {["x"] = 2, ["meta"] = {["fields"] = {["tubedir"] = "1"}, ["inventory"] = {}}, ["param2"] = 5, ["y"] = 2, ["param1"] = 31, ["z"] = 5, ["name"] = "pipeworks:tube_6"}, {["x"] = 2, ["meta"] = {["fields"] = {["infotext"] = "Node Breaker", ["owner"] = "singleplayer", ["formspec"] = "invsize[8,7;]item_image[0,0;1,1;pipeworks:nodebreaker_off]label[1,0;Node Breaker]list[current_name;pick;3.5,1;1,1;]list[current_player;main;0,3;8,4;]listring[]"}, ["inventory"] = {["ghost_pick"] = {":"}, ["main"] = {"", "", "", "", "", "", "", "", "", "", "", "", "", "", "", "", "", "", "", "", "", "", "", "", "", "", "", "", "", "", "", "", "", "", "", "", "", "", "", "", "", "", "", "", "", "", "", "", "", "", "", "", "", "", "", "", "", "", "", "", "", "", "", "", "", "", "", "", "", "", "", "", "", "", "", "", "", "", "", "", "", "", "", "", "", "", "", "", "", "", "", "", "", "", "", "", "", "", "", ""}, ["pick"] = {""}}}, ["param2"] = 0, ["y"] = 3, ["param1"] = 0, ["z"] = 4, ["name"] = "pipeworks:nodebreaker_off"}, {["x"] = 2, ["meta"] = {["fields"] = {["tubedir"] = "1"}, ["inventory"] = {}}, ["param2"] = 5, ["y"] = 3, ["param1"] = 31, ["z"] = 5, ["name"] = "pipeworks:tube_6"}, {["x"] = 2, ["meta"] = {["fields"] = {["infotext"] = "Node Breaker", ["owner"] = "singleplayer", ["formspec"] = "invsize[8,7;]item_image[0,0;1,1;pipeworks:nodebreaker_off]label[1,0;Node Breaker]list[current_name;pick;3.5,1;1,1;]list[current_player;main;0,3;8,4;]listring[]"}, ["inventory"] = {["ghost_pick"] = {":"}, ["main"] = {"", "", "", "", "", "", "", "", "", "", "", "", "", "", "", "", "", "", "", "", "", "", "", "", "", "", "", "", "", "", "", "", "", "", "", "", "", "", "", "", "", "", "", "", "", "", "", "", "", "", "", "", "", "", "", "", "", "", "", "", "", "", "", "", "", "", "", "", "", "", "", "", "", "", "", "", "", "", "", "", "", "", "", "", "", "", "", "", "", "", "", "", "", "", "", "", "", "", "", ""}, ["pick"] = {""}}}, ["param2"] = 0, ["y"] = 4, ["param1"] = 0, ["z"] = 4, ["name"] = "pipeworks:nodebreaker_off"}, {["x"] = 2, ["meta"] = {["fields"] = {["tubedir"] = "1"}, ["inventory"] = {}}, ["param2"] = 5, ["y"] = 4, ["param1"] = 31, ["z"] = 5, ["name"] = "pipeworks:tube_6"}, {["x"] = 2, ["meta"] = {["fields"] = {["infotext"] = "Node Breaker", ["owner"] = "singleplayer", ["formspec"] = "invsize[8,7;]item_image[0,0;1,1;pipeworks:nodebreaker_off]label[1,0;Node Breaker]list[current_name;pick;3.5,1;1,1;]list[current_player;main;0,3;8,4;]listring[]"}, ["inventory"] = {["ghost_pick"] = {":"}, ["main"] = {"", "", "", "", "", "", "", "", "", "", "", "", "", "", "", "", "", "", "", "", "", "", "", "", "", "", "", "", "", "", "", "", "", "", "", "", "", "", "", "", "", "", "", "", "", "", "", "", "", "", "", "", "", "", "", "", "", "", "", "", "", "", "", "", "", "", "", "", "", "", "", "", "", "", "", "", "", "", "", "", "", "", "", "", "", "", "", "", "", "", "", "", "", "", "", "", "", "", "", ""}, ["pick"] = {""}}}, ["param2"] = 0, ["y"] = 5, ["param1"] = 0, ["z"] = 4, ["name"] = "pipeworks:nodebreaker_off"}, {["x"] = 2, ["meta"] = {["fields"] = {["tubedir"] = "1"}, ["inventory"] = {}}, ["param2"] = 5, ["y"] = 5, ["param1"] = 31, ["z"] = 5, ["name"] = "pipeworks:tube_6"}, {["x"] = 2, ["meta"] = {["fields"] = {["infotext"] = "Node Breaker", ["owner"] = "singleplayer", ["formspec"] = "invsize[8,7;]item_image[0,0;1,1;pipeworks:nodebreaker_off]label[1,0;Node Breaker]list[current_name;pick;3.5,1;1,1;]list[current_player;main;0,3;8,4;]listring[]"}, ["inventory"] = {["ghost_pick"] = {":"}, ["main"] = {"", "", "", "", "", "", "", "", "", "", "", "", "", "", "", "", "", "", "", "", "", "", "", "", "", "", "", "", "", "", "", "", "", "", "", "", "", "", "", "", "", "", "", "", "", "", "", "", "", "", "", "", "", "", "", "", "", "", "", "", "", "", "", "", "", "", "", "", "", "", "", "", "", "", "", "", "", "", "", "", "", "", "", "", "", "", "", "", "", "", "", "", "", "", "", "", "", "", "", ""}, ["pick"] = {""}}}, ["param2"] = 0, ["y"] = 6, ["param1"] = 0, ["z"] = 4, ["name"] = "pipeworks:nodebreaker_off"}, {["x"] = 2, ["meta"] = {["fields"] = {["tubedir"] = "1"}, ["inventory"] = {}}, ["param2"] = 5, ["y"] = 6, ["param1"] = 31, ["z"] = 5, ["name"] = "pipeworks:tube_6"}, {["x"] = 2, ["meta"] = {["fields"] = {["infotext"] = "Node Breaker", ["owner"] = "singleplayer", ["formspec"] = "invsize[8,7;]item_image[0,0;1,1;pipeworks:nodebreaker_off]label[1,0;Node Breaker]list[current_name;pick;3.5,1;1,1;]list[current_player;main;0,3;8,4;]listring[]"}, ["inventory"] = {["ghost_pick"] = {":"}, ["main"] = {"", "", "", "", "", "", "", "", "", "", "", "", "", "", "", "", "", "", "", "", "", "", "", "", "", "", "", "", "", "", "", "", "", "", "", "", "", "", "", "", "", "", "", "", "", "", "", "", "", "", "", "", "", "", "", "", "", "", "", "", "", "", "", "", "", "", "", "", "", "", "", "", "", "", "", "", "", "", "", "", "", "", "", "", "", "", "", "", "", "", "", "", "", "", "", "", "", "", "", ""}, ["pick"] = {""}}}, ["param2"] = 0, ["y"] = 7, ["param1"] = 0, ["z"] = 4, ["name"] = "pipeworks:nodebreaker_off"}, {["x"] = 2, ["meta"] = {["fields"] = {["tubedir"] = "1"}, ["inventory"] = {}}, ["param2"] = 5, ["y"] = 7, ["param1"] = 31, ["z"] = 5, ["name"] = "pipeworks:tube_6"}, {["x"] = 2, ["meta"] = {["fields"] = {["infotext"] = "Node Breaker", ["owner"] = "singleplayer", ["formspec"] = "invsize[8,7;]item_image[0,0;1,1;pipeworks:nodebreaker_off]label[1,0;Node Breaker]list[current_name;pick;3.5,1;1,1;]list[current_player;main;0,3;8,4;]listring[]"}, ["inventory"] = {["ghost_pick"] = {":"}, ["main"] = {"", "", "", "", "", "", "", "", "", "", "", "", "", "", "", "", "", "", "", "", "", "", "", "", "", "", "", "", "", "", "", "", "", "", "", "", "", "", "", "", "", "", "", "", "", "", "", "", "", "", "", "", "", "", "", "", "", "", "", "", "", "", "", "", "", "", "", "", "", "", "", "", "", "", "", "", "", "", "", "", "", "", "", "", "", "", "", "", "", "", "", "", "", "", "", "", "", "", "", ""}, ["pick"] = {""}}}, ["param2"] = 0, ["y"] = 8, ["param1"] = 0, ["z"] = 4, ["name"] = "pipeworks:nodebreaker_off"}, {["x"] = 2, ["meta"] = {["fields"] = {["tubedir"] = "1"}, ["inventory"] = {}}, ["param2"] = 5, ["y"] = 8, ["param1"] = 31, ["z"] = 5, ["name"] = "pipeworks:tube_6"}, {["x"] = 2, ["meta"] = {["fields"] = {["infotext"] = "Node Breaker", ["owner"] = "singleplayer", ["formspec"] = "invsize[8,7;]item_image[0,0;1,1;pipeworks:nodebreaker_off]label[1,0;Node Breaker]list[current_name;pick;3.5,1;1,1;]list[current_player;main;0,3;8,4;]listring[]"}, ["inventory"] = {["ghost_pick"] = {":"}, ["main"] = {"", "", "", "", "", "", "", "", "", "", "", "", "", "", "", "", "", "", "", "", "", "", "", "", "", "", "", "", "", "", "", "", "", "", "", "", "", "", "", "", "", "", "", "", "", "", "", "", "", "", "", "", "", "", "", "", "", "", "", "", "", "", "", "", "", "", "", "", "", "", "", "", "", "", "", "", "", "", "", "", "", "", "", "", "", "", "", "", "", "", "", "", "", "", "", "", "", "", "", ""}, ["pick"] = {""}}}, ["param2"] = 0, ["y"] = 9, ["param1"] = 0, ["z"] = 4, ["name"] = "pipeworks:nodebreaker_off"}, {["x"] = 2, ["meta"] = {["fields"] = {["tubedir"] = "1"}, ["inventory"] = {}}, ["param2"] = 5, ["y"] = 9, ["param1"] = 31, ["z"] = 5, ["name"] = "pipeworks:tube_6"}, {["x"] = 2, ["meta"] = {["fields"] = {["infotext"] = "Node Breaker", ["owner"] = "singleplayer", ["formspec"] = "invsize[8,7;]item_image[0,0;1,1;pipeworks:nodebreaker_off]label[1,0;Node Breaker]list[current_name;pick;3.5,1;1,1;]list[current_player;main;0,3;8,4;]listring[]"}, ["inventory"] = {["ghost_pick"] = {":"}, ["main"] = {"", "", "", "", "", "", "", "", "", "", "", "", "", "", "", "", "", "", "", "", "", "", "", "", "", "", "", "", "", "", "", "", "", "", "", "", "", "", "", "", "", "", "", "", "", "", "", "", "", "", "", "", "", "", "", "", "", "", "", "", "", "", "", "", "", "", "", "", "", "", "", "", "", "", "", "", "", "", "", "", "", "", "", "", "", "", "", "", "", "", "", "", "", "", "", "", "", "", "", ""}, ["pick"] = {""}}}, ["param2"] = 20, ["y"] = 10, ["param1"] = 0, ["z"] = 4, ["name"] = "pipeworks:nodebreaker_off"}, {["x"] = 2, ["meta"] = {["fields"] = {["tubedir"] = "1"}, ["inventory"] = {}}, ["param2"] = 5, ["y"] = 10, ["param1"] = 31, ["z"] = 5, ["name"] = "pipeworks:tube_6"}, {["x"] = 2, ["meta"] = {["fields"] = {["infotext"] = "Node Breaker", ["owner"] = "singleplayer", ["formspec"] = "invsize[8,7;]item_image[0,0;1,1;pipeworks:nodebreaker_off]label[1,0;Node Breaker]list[current_name;pick;3.5,1;1,1;]list[current_player;main;0,3;8,4;]listring[]"}, ["inventory"] = {["ghost_pick"] = {":"}, ["main"] = {"", "", "", "", "", "", "", "", "", "", "", "", "", "", "", "", "", "", "", "", "", "", "", "", "", "", "", "", "", "", "", "", "", "", "", "", "", "", "", "", "", "", "", "", "", "", "", "", "", "", "", "", "", "", "", "", "", "", "", "", "", "", "", "", "", "", "", "", "", "", "", "", "", "", "", "", "", "", "", "", "", "", "", "", "", "", "", "", "", "", "", "", "", "", "", "", "", "", "", ""}, ["pick"] = {""}}}, ["param2"] = 20, ["y"] = 11, ["param1"] = 0, ["z"] = 4, ["name"] = "pipeworks:nodebreaker_off"}, {["x"] = 2, ["meta"] = {["fields"] = {["tubedir"] = "1"}, ["inventory"] = {}}, ["param2"] = 3, ["y"] = 11, ["param1"] = 31, ["z"] = 5, ["name"] = "pipeworks:tube_4"}, {["x"] = 3, ["meta"] = {["fields"] = {}, ["inventory"] = {}}, ["param2"] = 0, ["y"] = 0, ["param1"] = 0, ["z"] = 0, ["name"] = "default:dirt_with_grass"}, {["x"] = 3, ["meta"] = {["fields"] = {}, ["inventory"] = {}}, ["param2"] = 0, ["y"] = 0, ["param1"] = 0, ["z"] = 1, ["name"] = "default:dirt_with_grass"}, {["x"] = 3, ["meta"] = {["fields"] = {}, ["inventory"] = {}}, ["param2"] = 0, ["y"] = 0, ["param1"] = 0, ["z"] = 2, ["name"] = "default:dirt_with_grass"}, {["x"] = 3, ["meta"] = {["fields"] = {}, ["inventory"] = {}}, ["param2"] = 0, ["y"] = 0, ["param1"] = 0, ["z"] = 3, ["name"] = "default:dirt_with_grass"}, {["x"] = 3, ["meta"] = {["fields"] = {}, ["inventory"] = {}}, ["param2"] = 0, ["y"] = 0, ["param1"] = 0, ["z"] = 4, ["name"] = "default:dirt"}, {["x"] = 3, ["meta"] = {["fields"] = {}, ["inventory"] = {}}, ["param2"] = 0, ["y"] = 0, ["param1"] = 0, ["z"] = 5, ["name"] = "default:dirt"}, {["x"] = 3, ["meta"] = {["fields"] = {["dist"] = "8", ["infotext"] = "Adjustable Vacuuming Pneumatic Tube Segment (8m)", ["tubedir"] = "1", ["formspec"] = "size[2.1,0.8]image[0,0;1,1;pipeworks_mese_sand_tube_inv.png]field[1.3,0.4;1,1;dist;radius;${dist}]bgcolor[#080808BB;true]background[5,5;1,1;gui_formbg.png;true]"}, ["inventory"] = {}}, ["param2"] = 0, ["y"] = 1, ["param1"] = 15, ["z"] = 1, ["name"] = "pipeworks:mese_sand_tube_3"}, {["x"] = 3, ["meta"] = {["fields"] = {["dist"] = "8", ["infotext"] = "Adjustable Vacuuming Pneumatic Tube Segment (8m)", ["tubedir"] = "1", ["formspec"] = "size[2.1,0.8]image[0,0;1,1;pipeworks_mese_sand_tube_inv.png]field[1.3,0.4;1,1;dist;radius;${dist}]bgcolor[#080808BB;true]background[5,5;1,1;gui_formbg.png;true]"}, ["inventory"] = {}}, ["param2"] = 0, ["y"] = 1, ["param1"] = 15, ["z"] = 5, ["name"] = "pipeworks:mese_sand_tube_3"}, {["x"] = 4, ["meta"] = {["fields"] = {}, ["inventory"] = {}}, ["param2"] = 0, ["y"] = 0, ["param1"] = 0, ["z"] = 0, ["name"] = "default:dirt_with_grass"}, {["x"] = 4, ["meta"] = {["fields"] = {}, ["inventory"] = {}}, ["param2"] = 0, ["y"] = 0, ["param1"] = 0, ["z"] = 1, ["name"] = "default:dirt_with_grass"}, {["x"] = 4, ["meta"] = {["fields"] = {}, ["inventory"] = {}}, ["param2"] = 0, ["y"] = 0, ["param1"] = 0, ["z"] = 2, ["name"] = "default:dirt_with_grass"}, {["x"] = 4, ["meta"] = {["fields"] = {}, ["inventory"] = {}}, ["param2"] = 0, ["y"] = 0, ["param1"] = 0, ["z"] = 3, ["name"] = "default:dirt_with_grass"}, {["x"] = 4, ["meta"] = {["fields"] = {}, ["inventory"] = {}}, ["param2"] = 0, ["y"] = 0, ["param1"] = 0, ["z"] = 4, ["name"] = "default:dirt"}, {["x"] = 4, ["meta"] = {["fields"] = {}, ["inventory"] = {}}, ["param2"] = 0, ["y"] = 0, ["param1"] = 0, ["z"] = 5, ["name"] = "default:dirt_with_grass"}, {["x"] = 4, ["meta"] = {["fields"] = {["infotext"] = "Adjustable Vacuuming Pneumatic Tube Segment (8m)", ["dist"] = "8", ["tubedir"] = "1", ["formspec"] = "size[2.1,0.8]image[0,0;1,1;pipeworks_mese_sand_tube_inv.png]field[1.3,0.4;1,1;dist;radius;${dist}]bgcolor[#080808BB;true]background[5,5;1,1;gui_formbg.png;true]"}, ["inventory"] = {}}, ["param2"] = 8, ["y"] = 1, ["param1"] = 15, ["z"] = 1, ["name"] = "pipeworks:mese_sand_tube_4"}, {["x"] = 4, ["meta"] = {["fields"] = {["infotext"] = "Adjustable Vacuuming Pneumatic Tube Segment (8m)", ["dist"] = "8", ["tubedir"] = "1", ["formspec"] = "size[2.1,0.8]image[0,0;1,1;pipeworks_mese_sand_tube_inv.png]field[1.3,0.4;1,1;dist;radius;${dist}]bgcolor[#080808BB;true]background[5,5;1,1;gui_formbg.png;true]"}, ["inventory"] = {}}, ["param2"] = 1, ["y"] = 1, ["param1"] = 15, ["z"] = 2, ["name"] = "pipeworks:mese_sand_tube_3"}, {["x"] = 4, ["meta"] = {["fields"] = {["dist"] = "8", ["infotext"] = "Adjustable Vacuuming Pneumatic Tube Segment (8m)", ["tubedir"] = "1", ["formspec"] = "size[2.1,0.8]image[0,0;1,1;pipeworks_mese_sand_tube_inv.png]field[1.3,0.4;1,1;dist;radius;${dist}]bgcolor[#080808BB;true]background[5,5;1,1;gui_formbg.png;true]"}, ["inventory"] = {}}, ["param2"] = 1, ["y"] = 1, ["param1"] = 15, ["z"] = 3, ["name"] = "pipeworks:mese_sand_tube_3"}, {["x"] = 4, ["meta"] = {["fields"] = {["dist"] = "8", ["infotext"] = "Adjustable Vacuuming Pneumatic Tube Segment (8m)", ["tubedir"] = "1", ["formspec"] = "size[2.1,0.8]image[0,0;1,1;pipeworks_mese_sand_tube_inv.png]field[1.3,0.4;1,1;dist;radius;${dist}]bgcolor[#080808BB;true]background[5,5;1,1;gui_formbg.png;true]"}, ["inventory"] = {}}, ["param2"] = 1, ["y"] = 1, ["param1"] = 15, ["z"] = 4, ["name"] = "pipeworks:mese_sand_tube_3"}, {["x"] = 4, ["meta"] = {["fields"] = {["infotext"] = "Adjustable Vacuuming Pneumatic Tube Segment (8m)", ["dist"] = "8", ["tubedir"] = "1", ["formspec"] = "size[2.1,0.8]image[0,0;1,1;pipeworks_mese_sand_tube_inv.png]field[1.3,0.4;1,1;dist;radius;${dist}]bgcolor[#080808BB;true]background[5,5;1,1;gui_formbg.png;true]"}, ["inventory"] = {}}, ["param2"] = 4, ["y"] = 1, ["param1"] = 15, ["z"] = 5, ["name"] = "pipeworks:mese_sand_tube_4"}}